Workbook
Name Slicer_Device: #N/A

Sheet Pivot Table
A3: Device | B3: Sum of Clicks | C3: Sum of Impressions | D3: Sum of Cost | E3: Sum of Leads | F3: Sum of Conversions | G3: Sum of Sale_Amount
A4: Desktop | B4: 121887 | C4: 4019108.5 | D4: 190468.71 | E4: 17690 | F4: 5828 | G4: 1331958
A5: Mobile | B5: 123068 | C5: 3980624.5 | D5: 189809.84 | E5: 17647 | F5: 5799 | G5: 1314069
A6: Tablet | B6: 116338 | C6: 3760539 | D6: 179003.57 | E6: 16673 | F6: 5358 | G6: 1251341
A7: Grand Total | B7: 361293 | C7: 11760272 | D7: 559282.12 | E7: 52010 | F7: 16985 | G7: 3897368

Sheet Cleaned_Data
A1: Ad_ID | B1: Campaign_Name | C1: Clicks | D1: Impressions | E1: Cost | F1: Leads | G1: Conversions | H1: Conversion Rate | I1: Sale_Amount | J1: Ad_Date | K1: Location | L1: Device | M1: Keyword | N1: Clean_Date | O1: CTR | P1: CPC | Q1: CPL | R1: CPCONV | S1: ROAS
A2: A1000 | B2: Data Analytics Course | C2: 104 | D2: 4498 | E2: 231.88 | F2: 14 | G2: 7 | H2: 0.058 | I2: 1892 | J2: 45612 | K2: Hyderabad | L2: Desktop | M2: learn data analytics | N2: =IF(A2="","",IF(ISNUMBER(J2),J2,IF(MID(J2,5,1)="-",DATE(LEFT(J2,4),MID(J2,6,2),RIGHT(J2,2)),IF(MID(J2,5,1)="/",DATE(LEFT(J2,4),MID(J2,6,2),RIGHT(J2,2)),DATE(RIGHT(J2,4),MID(J2,4,2),LEFT(J2,2)))))) -> 45612 | O2: =IFERROR(C2/D2,0) -> 0.023121387 | P2: =IFERROR(E2/C2,0) -> 2.2296154 | Q2: =IFERROR(E2/F2,0) -> 16.562857 | R2: =IFERROR(E2/G2,0) -> 33.125714 | S2: =IFERROR(I2/E2,0) -> 8.1593928
A3: A1001 | B3: Data Analytics Course | C3: 173 | D3: 5107 | E3: 216.84 | F3: 10 | G3: 8 | H3: 0.046 | I3: 1679 | J3: 20-11-2024 | K3: Hyderabad | L3: Mobile | M3: data analytics course | N3: =IF(A3="","",IF(ISNUMBER(J3),J3,IF(MID(J3,5,1)="-",DATE(LEFT(J3,4),MID(J3,6,2),RIGHT(J3,2)),IF(MID(J3,5,1)="/",DATE(LEFT(J3,4),MID(J3,6,2),RIGHT(J3,2)),DATE(RIGHT(J3,4),MID(J3,4,2),LEFT(J3,2)))))) -> 45616 | O3: =IFERROR(C3/D3,0) -> 0.033875073 | P3: =IFERROR(E3/C3,0) -> 1.2534104 | Q3: =IFERROR(E3/F3,0) -> 21.684 | R3: =IFERROR(E3/G3,0) -> 27.105 | S3: =IFERROR(I3/E3,0) -> 7.7430363
A4: A1002 | B4: Data Analytics Course | C4: 90 | D4: 4544 | E4: 203.66 | F4: 26 | G4: 9 | H4: 0.046 | I4: 1624 | J4: 45612 | K4: Hyderabad | L4: Desktop | M4: data analitics online | N4: =IF(A4="","",IF(ISNUMBER(J4),J4,IF(MID(J4,5,1)="-",DATE(LEFT(J4,4),MID(J4,6,2),RIGHT(J4,2)),IF(MID(J4,5,1)="/",DATE(LEFT(J4,4),MID(J4,6,2),RIGHT(J4,2)),DATE(RIGHT(J4,4),MID(J4,4,2),LEFT(J4,2)))))) -> 45612 | O4: =IFERROR(C4/D4,0) -> 0.019806338 | P4: =IFERROR(E4/C4,0) -> 2.2628889 | Q4: =IFERROR(E4/F4,0) -> 7.8330769 | R4: =IFERROR(E4/G4,0) -> 22.628889 | S4: =IFERROR(I4/E4,0) -> 7.9740744
A5: A1003 | B5: Data Analytics Course | C5: 142 | D5: 3185 | E5: 237.66 | F5: 17 | G5: 6 | H5: 0.046 | I5: 1225 | J5: 45622 | K5: Hyderabad | L5: Tablet | M5: data anaytics training | N5: =IF(A5="","",IF(ISNUMBER(J5),J5,IF(MID(J5,5,1)="-",DATE(LEFT(J5,4),MID(J5,6,2),RIGHT(J5,2)),IF(MID(J5,5,1)="/",DATE(LEFT(J5,4),MID(J5,6,2),RIGHT(J5,2)),DATE(RIGHT(J5,4),MID(J5,4,2),LEFT(J5,2)))))) -> 45622 | O5: =IFERROR(C5/D5,0) -> 0.044583987 | P5: =IFERROR(E5/C5,0) -> 1.673662 | Q5: =IFERROR(E5/F5,0) -> 13.98 | R5: =IFERROR(E5/G5,0) -> 39.61 | S5: =IFERROR(I5/E5,0) -> 5.1544223
A6: A1004 | B6: Data Analytics Course | C6: 156 | D6: 3361 | E6: 195.9 | F6: 30 | G6: 8 | H6: 0.046 | I6: 1091 | J6: 45618 | K6: Hyderabad | L6: Desktop | M6: online data analytic | N6: =IF(A6="","",IF(ISNUMBER(J6),J6,IF(MID(J6,5,1)="-",DATE(LEFT(J6,4),MID(J6,6,2),RIGHT(J6,2)),IF(MID(J6,5,1)="/",DATE(LEFT(J6,4),MID(J6,6,2),RIGHT(J6,2)),DATE(RIGHT(J6,4),MID(J6,4,2),LEFT(J6,2)))))) -> 45618 | O6: =IFERROR(C6/D6,0) -> 0.046414758 | P6: =IFERROR(E6/C6,0) -> 1.2557692 | Q6: =IFERROR(E6/F6,0) -> 6.53 | R6: =IFERROR(E6/G6,0) -> 24.4875 | S6: =IFERROR(I6/E6,0) -> 5.5691679
A7: A1005 | B7: Data Analytics Course | C7: 195 | D7: 3776 | E7: 243.57 | F7: 10 | G7: 8 | H7: 0.046 | I7: 1315 | J7: 16-11-2024 | K7: Hyderabad | L7: Mobile | M7: data anaytics training | N7: =IF(A7="","",IF(ISNUMBER(J7),J7,IF(MID(J7,5,1)="-",DATE(LEFT(J7,4),MID(J7,6,2),RIGHT(J7,2)),IF(MID(J7,5,1)="/",DATE(LEFT(J7,4),MID(J7,6,2),RIGHT(J7,2)),DATE(RIGHT(J7,4),MID(J7,4,2),LEFT(J7,2)))))) -> 45612 | O7: =IFERROR(C7/D7,0) -> 0.051641949 | P7: =IFERROR(E7/C7,0) -> 1.2490769 | Q7: =IFERROR(E7/F7,0) -> 24.357 | R7: =IFERROR(E7/G7,0) -> 30.44625 | S7: =IFERROR(I7/E7,0) -> 5.3988586
A8: A1006 | B8: Data Analytics Course | C8: 116 | D8: 4480 | E8: 237.79 | F8: 17 | G8: 5 | H8: 0.043 | I8: 1640 | J8: 45454 | K8: Hyderabad | L8: Tablet | M8: data analytics course | N8: =IF(A8="","",IF(ISNUMBER(J8),J8,IF(MID(J8,5,1)="-",DATE(LEFT(J8,4),MID(J8,6,2),RIGHT(J8,2)),IF(MID(J8,5,1)="/",DATE(LEFT(J8,4),MID(J8,6,2),RIGHT(J8,2)),DATE(RIGHT(J8,4),MID(J8,4,2),LEFT(J8,2)))))) -> 45454 | O8: =IFERROR(C8/D8,0) -> 0.025892857 | P8: =IFERROR(E8/C8,0) -> 2.0499138 | Q8: =IFERROR(E8/F8,0) -> 13.987647 | R8: =IFERROR(E8/G8,0) -> 47.558 | S8: =IFERROR(I8/E8,0) -> 6.8968418
A9: A1007 | B9: Data Analytics Course | C9: 184 | D9: 5060 | E9: 229.61 | F9: 23 | G9: 3 | H9: 0.016 | I9: 1509 | J9: 45620 | K9: Hyderabad | L9: Tablet | M9: analytics for data | N9: =IF(A9="","",IF(ISNUMBER(J9),J9,IF(MID(J9,5,1)="-",DATE(LEFT(J9,4),MID(J9,6,2),RIGHT(J9,2)),IF(MID(J9,5,1)="/",DATE(LEFT(J9,4),MID(J9,6,2),RIGHT(J9,2)),DATE(RIGHT(J9,4),MID(J9,4,2),LEFT(J9,2)))))) -> 45620 | O9: =IFERROR(C9/D9,0) -> 0.036363636 | P9: =IFERROR(E9/C9,0) -> 1.2478804 | Q9: =IFERROR(E9/F9,0) -> 9.9830435 | R9: =IFERROR(E9/G9,0) -> 76.536667 | S9: =IFERROR(I9/E9,0) -> 6.5720134
A10: A1008 | B10: Data Analytics Course | C10: 113 | D10: 5434 | E10: 215.57 | F10: 27 | G10: 4 | H10: 0.058 | I10: 1362 | J10: 45620 | K10: Hyderabad | L10: Tablet | M10: data anaytics training | N10: =IF(A10="","",IF(ISNUMBER(J10),J10,IF(MID(J10,5,1)="-",DATE(LEFT(J10,4),MID(J10,6,2),RIGHT(J10,2)),IF(MID(J10,5,1)="/",DATE(LEFT(J10,4),MID(J10,6,2),RIGHT(J10,2)),DATE(RIGHT(J10,4),MID(J10,4,2),LEFT(J10,2)))))) -> 45620 | O10: =IFERROR(C10/D10,0) -> 0.020794994 | P10: =IFERROR(E10/C10,0) -> 1.9076991 | Q10: =IFERROR(E10/F10,0) -> 7.9840741 | R10: =IFERROR(E10/G10,0) -> 53.8925 | S10: =IFERROR(I10/E10,0) -> 6.3181333
A11: A1009 | B11: Data Analytics Course | C11: 166 | D11: 3355 | E11: 186.78 | F11: 24 | G11: 9 | H11: 0.054 | I11: 1029 | J11: 45608 | K11: Hyderabad | L11: Mobile | M11: online data analytic | N11: =IF(A11="","",IF(ISNUMBER(J11),J11,IF(MID(J11,5,1)="-",DATE(LEFT(J11,4),MID(J11,6,2),RIGHT(J11,2)),IF(MID(J11,5,1)="/",DATE(LEFT(J11,4),MID(J11,6,2),RIGHT(J11,2)),DATE(RIGHT(J11,4),MID(J11,4,2),LEFT(J11,2)))))) -> 45608 | O11: =IFERROR(C11/D11,0) -> 0.04947839 | P11: =IFERROR(E11/C11,0) -> 1.1251807 | Q11: =IFERROR(E11/F11,0) -> 7.7825 | R11: =IFERROR(E11/G11,0) -> 20.753333 | S11: =IFERROR(I11/E11,0) -> 5.5091552
A12: A1010 | B12: Data Analytics Course | C12: 101 | D12: 5399 | E12: 236.79 | F12: 20 | G12: 6 | H12: 0.059 | I12: 1900 | J12: 14-11-2024 | K12: Hyderabad | L12: Desktop | M12: learn data analytics | N12: =IF(A12="","",IF(ISNUMBER(J12),J12,IF(MID(J12,5,1)="-",DATE(LEFT(J12,4),MID(J12,6,2),RIGHT(J12,2)),IF(MID(J12,5,1)="/",DATE(LEFT(J12,4),MID(J12,6,2),RIGHT(J12,2)),DATE(RIGHT(J12,4),MID(J12,4,2),LEFT(J12,2)))))) -> 45610 | O12: =IFERROR(C12/D12,0) -> 0.018707168 | P12: =IFERROR(E12/C12,0) -> 2.3444554 | Q12: =IFERROR(E12/F12,0) -> 11.8395 | R12: =IFERROR(E12/G12,0) -> 39.465 | S12: =IFERROR(I12/E12,0) -> 8.0239875
A13: A1011 | B13: Data Analytics Course | C13: 101 | D13: 3613 | E13: 208.12 | F13: 24 | G13: 5 | H13: 0.05 | I13: 1130 | J13: 45618 | K13: Hyderabad | L13: Desktop | M13: online data analytic | N13: =IF(A13="","",IF(ISNUMBER(J13),J13,IF(MID(J13,5,1)="-",DATE(LEFT(J13,4),MID(J13,6,2),RIGHT(J13,2)),IF(MID(J13,5,1)="/",DATE(LEFT(J13,4),MID(J13,6,2),RIGHT(J13,2)),DATE(RIGHT(J13,4),MID(J13,4,2),LEFT(J13,2)))))) -> 45618 | O13: =IFERROR(C13/D13,0) -> 0.027954608 | P13: =IFERROR(E13/C13,0) -> 2.0605941 | Q13: =IFERROR(E13/F13,0) -> 8.6716667 | R13: =IFERROR(E13/G13,0) -> 41.624 | S13: =IFERROR(I13/E13,0) -> 5.4295599
A14: A1012 | B14: Data Analytics Course | C14: 125 | D14: 3259 | E14: 191.3 | F14: 18 | G14: 3 | H14: 0.024 | I14: 1959 | J14: 45623 | K14: Hyderabad | L14: Desktop | M14: data analitics online | N14: =IF(A14="","",IF(ISNUMBER(J14),J14,IF(MID(J14,5,1)="-",DATE(LEFT(J14,4),MID(J14,6,2),RIGHT(J14,2)),IF(MID(J14,5,1)="/",DATE(LEFT(J14,4),MID(J14,6,2),RIGHT(J14,2)),DATE(RIGHT(J14,4),MID(J14,4,2),LEFT(J14,2)))))) -> 45623 | O14: =IFERROR(C14/D14,0) -> 0.038355324 | P14: =IFERROR(E14/C14,0) -> 1.5304 | Q14: =IFERROR(E14/F14,0) -> 10.627778 | R14: =IFERROR(E14/G14,0) -> 63.766667 | S14: =IFERROR(I14/E14,0) -> 10.24046
A15: A1013 | B15: Data Analytics Course | C15: 196 | D15: 3742 | E15: 207.46 | F15: 10 | G15: 7 | H15: 0.038 | I15: 1623 | J15: 45637 | K15: Hyderabad | L15: Mobile | M15: data anaytics training | N15: =IF(A15="","",IF(ISNUMBER(J15),J15,IF(MID(J15,5,1)="-",DATE(LEFT(J15,4),MID(J15,6,2),RIGHT(J15,2)),IF(MID(J15,5,1)="/",DATE(LEFT(J15,4),MID(J15,6,2),RIGHT(J15,2)),DATE(RIGHT(J15,4),MID(J15,4,2),LEFT(J15,2)))))) -> 45637 | O15: =IFERROR(C15/D15,0) -> 0.052378407 | P15: =IFERROR(E15/C15,0) -> 1.0584694 | Q15: =IFERROR(E15/F15,0) -> 20.746 | R15: =IFERROR(E15/G15,0) -> 29.637143 | S15: =IFERROR(I15/E15,0) -> 7.8231948
A16: A1014 | B16: Data Analytics Course | C16: 181 | D16: 4311 | E16: 185.09 | F16: 11 | G16: 9 | H16: 0.05 | I16: 1538 | J16: 45600 | K16: Hyderabad | L16: Desktop | M16: data anaytics training | N16: =IF(A16="","",IF(ISNUMBER(J16),J16,IF(MID(J16,5,1)="-",DATE(LEFT(J16,4),MID(J16,6,2),RIGHT(J16,2)),IF(MID(J16,5,1)="/",DATE(LEFT(J16,4),MID(J16,6,2),RIGHT(J16,2)),DATE(RIGHT(J16,4),MID(J16,4,2),LEFT(J16,2)))))) -> 45600 | O16: =IFERROR(C16/D16,0) -> 0.041985618 | P16: =IFERROR(E16/C16,0) -> 1.0225967 | Q16: =IFERROR(E16/F16,0) -> 16.826364 | R16: =IFERROR(E16/G16,0) -> 20.565556 | S16: =IFERROR(I16/E16,0) -> 8.3094711
A17: A1015 | B17: Data Analytics Course | C17: 102 | D17: 5461 | E17: 201.69 | F17: 22 | G17: 8 | H17: 0.078 | I17: 1755 | J17: 45625 | K17: Hyderabad | L17: Desktop | M17: data analytics course | N17: =IF(A17="","",IF(ISNUMBER(J17),J17,IF(MID(J17,5,1)="-",DATE(LEFT(J17,4),MID(J17,6,2),RIGHT(J17,2)),IF(MID(J17,5,1)="/",DATE(LEFT(J17,4),MID(J17,6,2),RIGHT(J17,2)),DATE(RIGHT(J17,4),MID(J17,4,2),LEFT(J17,2)))))) -> 45625 | O17: =IFERROR(C17/D17,0) -> 0.018677898 | P17: =IFERROR(E17/C17,0) -> 1.9773529 | Q17: =IFERROR(E17/F17,0) -> 9.1677273 | R17: =IFERROR(E17/G17,0) -> 25.21125 | S17: =IFERROR(I17/E17,0) -> 8.7014726
A18: A1016 | B18: Data Analytics Course | C18: 193 | D18: 5159 | E18: 215.57 | F18: 15 | G18: 9 | H18: 0.047 | I18: 1614 | J18: 45606 | K18: Hyderabad | L18: Mobile | M18: learn data analytics | N18: =IF(A18="","",IF(ISNUMBER(J18),J18,IF(MID(J18,5,1)="-",DATE(LEFT(J18,4),MID(J18,6,2),RIGHT(J18,2)),IF(MID(J18,5,1)="/",DATE(LEFT(J18,4),MID(J18,6,2),RIGHT(J18,2)),DATE(RIGHT(J18,4),MID(J18,4,2),LEFT(J18,2)))))) -> 45606 | O18: =IFERROR(C18/D18,0) -> 0.037410351 | P18: =IFERROR(E18/C18,0) -> 1.116943 | Q18: =IFERROR(E18/F18,0) -> 14.371333 | R18: =IFERROR(E18/G18,0) -> 23.952222 | S18: =IFERROR(I18/E18,0) -> 7.4871272
A19: A1017 | B19: Data Analytics Course | C19: 149 | D19: 4431 | E19: 207.4 | F19: 19 | G19: 9 | H19: 0.06 | I19: 1693 | J19: 45637 | K19: Hyderabad | L19: Mobile | M19: learn data analytics | N19: =IF(A19="","",IF(ISNUMBER(J19),J19,IF(MID(J19,5,1)="-",DATE(LEFT(J19,4),MID(J19,6,2),RIGHT(J19,2)),IF(MID(J19,5,1)="/",DATE(LEFT(J19,4),MID(J19,6,2),RIGHT(J19,2)),DATE(RIGHT(J19,4),MID(J19,4,2),LEFT(J19,2)))))) -> 45637 | O19: =IFERROR(C19/D19,0) -> 0.033626721 | P19: =IFERROR(E19/C19,0) -> 1.3919463 | Q19: =IFERROR(E19/F19,0) -> 10.915789 | R19: =IFERROR(E19/G19,0) -> 23.044444 | S19: =IFERROR(I19/E19,0) -> 8.1629701
A20: A1018 | B20: Data Analytics Course | C20: 150 | D20: 3113 | E20: 217.41 | F20: 20 | G20: 5 | H20: 0.046 | I20: 1785 | J20: 45603 | K20: Hyderabad | L20: Mobile | M20: analytics for data | N20: =IF(A20="","",IF(ISNUMBER(J20),J20,IF(MID(J20,5,1)="-",DATE(LEFT(J20,4),MID(J20,6,2),RIGHT(J20,2)),IF(MID(J20,5,1)="/",DATE(LEFT(J20,4),MID(J20,6,2),RIGHT(J20,2)),DATE(RIGHT(J20,4),MID(J20,4,2),LEFT(J20,2)))))) -> 45603 | O20: =IFERROR(C20/D20,0) -> 0.048185031 | P20: =IFERROR(E20/C20,0) -> 1.4494 | Q20: =IFERROR(E20/F20,0) -> 10.8705 | R20: =IFERROR(E20/G20,0) -> 43.482 | S20: =IFERROR(I20/E20,0) -> 8.2102939
A21: A1019 | B21: Data Analytics Course | C21: 145 | D21: 5278 | E21: 215.57 | F21: 25 | G21: 6 | H21: 0.041 | I21: 1516 | J21: 45601 | K21: Hyderabad | L21: Desktop | M21: data analytics course | N21: =IF(A21="","",IF(ISNUMBER(J21),J21,IF(MID(J21,5,1)="-",DATE(LEFT(J21,4),MID(J21,6,2),RIGHT(J21,2)),IF(MID(J21,5,1)="/",DATE(LEFT(J21,4),MID(J21,6,2),RIGHT(J21,2)),DATE(RIGHT(J21,4),MID(J21,4,2),LEFT(J21,2)))))) -> 45601 | O21: =IFERROR(C21/D21,0) -> 0.027472527 | P21: =IFERROR(E21/C21,0) -> 1.4866897 | Q21: =IFERROR(E21/F21,0) -> 8.6228 | R21: =IFERROR(E21/G21,0) -> 35.928333 | S21: =IFERROR(I21/E21,0) -> 7.0325184
A22: A1020 | B22: Data Analytics Course | C22: 184 | D22: 4143 | E22: 223.3 | F22: 10 | G22: 10 | H22: 0.044 | I22: 1735 | J22: 45617 | K22: Hyderabad | L22: Tablet | M22: learn data analytics | N22: =IF(A22="","",IF(ISNUMBER(J22),J22,IF(MID(J22,5,1)="-",DATE(LEFT(J22,4),MID(J22,6,2),RIGHT(J22,2)),IF(MID(J22,5,1)="/",DATE(LEFT(J22,4),MID(J22,6,2),RIGHT(J22,2)),DATE(RIGHT(J22,4),MID(J22,4,2),LEFT(J22,2)))))) -> 45617 | O22: =IFERROR(C22/D22,0) -> 0.044412262 | P22: =IFERROR(E22/C22,0) -> 1.213587 | Q22: =IFERROR(E22/F22,0) -> 22.33 | R22: =IFERROR(E22/G22,0) -> 22.33 | S22: =IFERROR(I22/E22,0) -> 7.7698164
A23: A1021 | B23: Data Analytics Course | C23: 171 | D23: 4154 | E23: 184.23 | F23: 30 | G23: 7 | H23: 0.041 | I23: 1803 | J23: 45604 | K23: Hyderabad | L23: Tablet | M23: data analitics online | N23: =IF(A23="","",IF(ISNUMBER(J23),J23,IF(MID(J23,5,1)="-",DATE(LEFT(J23,4),MID(J23,6,2),RIGHT(J23,2)),IF(MID(J23,5,1)="/",DATE(LEFT(J23,4),MID(J23,6,2),RIGHT(J23,2)),DATE(RIGHT(J23,4),MID(J23,4,2),LEFT(J23,2)))))) -> 45604 | O23: =IFERROR(C23/D23,0) -> 0.041165142 | P23: =IFERROR(E23/C23,0) -> 1.0773684 | Q23: =IFERROR(E23/F23,0) -> 6.141 | R23: =IFERROR(E23/G23,0) -> 26.318571 | S23: =IFERROR(I23/E23,0) -> 9.7866797
A24: A1022 | B24: Data Analytics Course | C24: 122 | D24: 5187 | E24: 211.24 | F24: 27 | G24: 6 | H24: 0.049 | I24: 1322 | J24: 45616 | K24: Hyderabad | L24: Desktop | M24: online data analytic | N24: =IF(A24="","",IF(ISNUMBER(J24),J24,IF(MID(J24,5,1)="-",DATE(LEFT(J24,4),MID(J24,6,2),RIGHT(J24,2)),IF(MID(J24,5,1)="/",DATE(LEFT(J24,4),MID(J24,6,2),RIGHT(J24,2)),DATE(RIGHT(J24,4),MID(J24,4,2),LEFT(J24,2)))))) -> 45616 | O24: =IFERROR(C24/D24,0) -> 0.023520339 | P24: =IFERROR(E24/C24,0) -> 1.7314754 | Q24: =IFERROR(E24/F24,0) -> 7.8237037 | R24: =IFERROR(E24/G24,0) -> 35.206667 | S24: =IFERROR(I24/E24,0) -> 6.2582844
A25: A1023 | B25: Data Analytics Course | C25: 188 | D25: 5798 | E25: 230.17 | F25: 28 | G25: 5 | H25: 0.047 | I25: 1452 | J25: 30-11-2024 | K25: Hyderabad | L25: Tablet | M25: data analytics course | N25: =IF(A25="","",IF(ISNUMBER(J25),J25,IF(MID(J25,5,1)="-",DATE(LEFT(J25,4),MID(J25,6,2),RIGHT(J25,2)),IF(MID(J25,5,1)="/",DATE(LEFT(J25,4),MID(J25,6,2),RIGHT(J25,2)),DATE(RIGHT(J25,4),MID(J25,4,2),LEFT(J25,2)))))) -> 45626 | O25: =IFERROR(C25/D25,0) -> 0.032424974 | P25: =IFERROR(E25/C25,0) -> 1.2243085 | Q25: =IFERROR(E25/F25,0) -> 8.2203571 | R25: =IFERROR(E25/G25,0) -> 46.034 | S25: =IFERROR(I25/E25,0) -> 6.3083808
A26: A1024 | B26: Data Analytics Course | C26: 87 | D26: 3718 | E26: 215.57 | F26: 12 | G26: 3 | H26: 0.034 | I26: 1652 | J26: 20-11-2024 | K26: Hyderabad | L26: Tablet | M26: learn data analytics | N26: =IF(A26="","",IF(ISNUMBER(J26),J26,IF(MID(J26,5,1)="-",DATE(LEFT(J26,4),MID(J26,6,2),RIGHT(J26,2)),IF(MID(J26,5,1)="/",DATE(LEFT(J26,4),MID(J26,6,2),RIGHT(J26,2)),DATE(RIGHT(J26,4),MID(J26,4,2),LEFT(J26,2)))))) -> 45616 | O26: =IFERROR(C26/D26,0) -> 0.023399677 | P26: =IFERROR(E26/C26,0) -> 2.4778161 | Q26: =IFERROR(E26/F26,0) -> 17.964167 | R26: =IFERROR(E26/G26,0) -> 71.856667 | S26: =IFERROR(I26/E26,0) -> 7.663404
A27: A1025 | B27: Data Analytics Course | C27: 88 | D27: 3349 | E27: 181.92 | F27: 22 | G27: 8 | H27: 0.091 | I27: 1456 | J27: 45616 | K27: Hyderabad | L27: Tablet | M27: learn data analytics | N27: =IF(A27="","",IF(ISNUMBER(J27),J27,IF(MID(J27,5,1)="-",DATE(LEFT(J27,4),MID(J27,6,2),RIGHT(J27,2)),IF(MID(J27,5,1)="/",DATE(LEFT(J27,4),MID(J27,6,2),RIGHT(J27,2)),DATE(RIGHT(J27,4),MID(J27,4,2),LEFT(J27,2)))))) -> 45616 | O27: =IFERROR(C27/D27,0) -> 0.0262765 | P27: =IFERROR(E27/C27,0) -> 2.0672727 | Q27: =IFERROR(E27/F27,0) -> 8.2690909 | R27: =IFERROR(E27/G27,0) -> 22.74 | S27: =IFERROR(I27/E27,0) -> 8.003518
A28: A1026 | B28: Data Analytics Course | C28: 119 | D28: 5323 | E28: 205.92 | F28: 17 | G28: 10 | H28: 0.06 | I28: 1656 | J28: 45598 | K28: Hyderabad | L28: Desktop | M28: online data analytic | N28: =IF(A28="","",IF(ISNUMBER(J28),J28,IF(MID(J28,5,1)="-",DATE(LEFT(J28,4),MID(J28,6,2),RIGHT(J28,2)),IF(MID(J28,5,1)="/",DATE(LEFT(J28,4),MID(J28,6,2),RIGHT(J28,2)),DATE(RIGHT(J28,4),MID(J28,4,2),LEFT(J28,2)))))) -> 45598 | O28: =IFERROR(C28/D28,0) -> 0.022355814 | P28: =IFERROR(E28/C28,0) -> 1.7304202 | Q28: =IFERROR(E28/F28,0) -> 12.112941 | R28: =IFERROR(E28/G28,0) -> 20.592 | S28: =IFERROR(I28/E28,0) -> 8.041958
A29: A1027 | B29: Data Analytics Course | C29: 139 | D29: 5286 | E29: 234.89 | F29: 22 | G29: 10 | H29: 0.046 | I29: 1688 | J29: 45617 | K29: Hyderabad | L29: Desktop | M29: data anaytics training | N29: =IF(A29="","",IF(ISNUMBER(J29),J29,IF(MID(J29,5,1)="-",DATE(LEFT(J29,4),MID(J29,6,2),RIGHT(J29,2)),IF(MID(J29,5,1)="/",DATE(LEFT(J29,4),MID(J29,6,2),RIGHT(J29,2)),DATE(RIGHT(J29,4),MID(J29,4,2),LEFT(J29,2)))))) -> 45617 | O29: =IFERROR(C29/D29,0) -> 0.026295876 | P29: =IFERROR(E29/C29,0) -> 1.6898561 | Q29: =IFERROR(E29/F29,0) -> 10.676818 | R29: =IFERROR(E29/G29,0) -> 23.489 | S29: =IFERROR(I29/E29,0) -> 7.1863425
A30: A1028 | B30: Data Analytics Course | C30: 128 | D30: 5469 | E30: 188.49 | F30: 16 | G30: 3 | H30: 0.046 | I30: 1783 | J30: 45619 | K30: Hyderabad | L30: Mobile | M30: learn data analytics | N30: =IF(A30="","",IF(ISNUMBER(J30),J30,IF(MID(J30,5,1)="-",DATE(LEFT(J30,4),MID(J30,6,2),RIGHT(J30,2)),IF(MID(J30,5,1)="/",DATE(LEFT(J30,4),MID(J30,6,2),RIGHT(J30,2)),DATE(RIGHT(J30,4),MID(J30,4,2),LEFT(J30,2)))))) -> 45619 | O30: =IFERROR(C30/D30,0) -> 0.023404644 | P30: =IFERROR(E30/C30,0) -> 1.4725781 | Q30: =IFERROR(E30/F30,0) -> 11.780625 | R30: =IFERROR(E30/G30,0) -> 62.83 | S30: =IFERROR(I30/E30,0) -> 9.4593878
A31: A1029 | B31: Data Analytics Course | C31: 86 | D31: 3351 | E31: 237.75 | F31: 21 | G31: 9 | H31: 0.105 | I31: 1975 | J31: 45609 | K31: Hyderabad | L31: Mobile | M31: analytics for data | N31: =IF(A31="","",IF(ISNUMBER(J31),J31,IF(MID(J31,5,1)="-",DATE(LEFT(J31,4),MID(J31,6,2),RIGHT(J31,2)),IF(MID(J31,5,1)="/",DATE(LEFT(J31,4),MID(J31,6,2),RIGHT(J31,2)),DATE(RIGHT(J31,4),MID(J31,4,2),LEFT(J31,2)))))) -> 45609 | O31: =IFERROR(C31/D31,0) -> 0.025663981 | P31: =IFERROR(E31/C31,0) -> 2.7645349 | Q31: =IFERROR(E31/F31,0) -> 11.321429 | R31: =IFERROR(E31/G31,0) -> 26.416667 | S31: =IFERROR(I31/E31,0) -> 8.3070452
A32: A1030 | B32: Data Analytics Course | C32: 188 | D32: 4834 | E32: 213.58 | F32: 15 | G32: 4 | H32: 0.021 | I32: 1590 | J32: 45604 | K32: Hyderabad | L32: Tablet | M32: online data analytic | N32: =IF(A32="","",IF(ISNUMBER(J32),J32,IF(MID(J32,5,1)="-",DATE(LEFT(J32,4),MID(J32,6,2),RIGHT(J32,2)),IF(MID(J32,5,1)="/",DATE(LEFT(J32,4),MID(J32,6,2),RIGHT(J32,2)),DATE(RIGHT(J32,4),MID(J32,4,2),LEFT(J32,2)))))) -> 45604 | O32: =IFERROR(C32/D32,0) -> 0.038891187 | P32: =IFERROR(E32/C32,0) -> 1.1360638 | Q32: =IFERROR(E32/F32,0) -> 14.238667 | R32: =IFERROR(E32/G32,0) -> 53.395 | S32: =IFERROR(I32/E32,0) -> 7.4445173
A33: A1031 | B33: Data Analytics Course | C33: 113 | D33: 5065 | E33: 212.37 | F33: 11 | G33: 5 | H33: 0.046 | I33: 1111 | J33: 22-11-2024 | K33: Hyderabad | L33: Desktop | M33: online data analytic | N33: =IF(A33="","",IF(ISNUMBER(J33),J33,IF(MID(J33,5,1)="-",DATE(LEFT(J33,4),MID(J33,6,2),RIGHT(J33,2)),IF(MID(J33,5,1)="/",DATE(LEFT(J33,4),MID(J33,6,2),RIGHT(J33,2)),DATE(RIGHT(J33,4),MID(J33,4,2),LEFT(J33,2)))))) -> 45618 | O33: =IFERROR(C33/D33,0) -> 0.02230997 | P33: =IFERROR(E33/C33,0) -> 1.8793805 | Q33: =IFERROR(E33/F33,0) -> 19.306364 | R33: =IFERROR(E33/G33,0) -> 42.474 | S33: =IFERROR(I33/E33,0) -> 5.2314357
A34: A1032 | B34: Data Analytics Course | C34: 139 | D34: 3872 | E34: 244.38 | F34: 20 | G34: 4 | H34: 0.046 | I34: 1041 | J34: 45637 | K34: Hyderabad | L34: Tablet | M34: data analitics online | N34: =IF(A34="","",IF(ISNUMBER(J34),J34,IF(MID(J34,5,1)="-",DATE(LEFT(J34,4),MID(J34,6,2),RIGHT(J34,2)),IF(MID(J34,5,1)="/",DATE(LEFT(J34,4),MID(J34,6,2),RIGHT(J34,2)),DATE(RIGHT(J34,4),MID(J34,4,2),LEFT(J34,2)))))) -> 45637 | O34: =IFERROR(C34/D34,0) -> 0.03589876 | P34: =IFERROR(E34/C34,0) -> 1.7581295 | Q34: =IFERROR(E34/F34,0) -> 12.219 | R34: =IFERROR(E34/G34,0) -> 61.095 | S34: =IFERROR(I34/E34,0) -> 4.2597594
A35: A1033 | B35: Data Analytics Course | C35: 176 | D35: 5509 | E35: 234.59 | F35: 19 | G35: 7 | H35: 0.054 | I35: 1710 | J35: 45599 | K35: Hyderabad | L35: Tablet | M35: data analytics course | N35: =IF(A35="","",IF(ISNUMBER(J35),J35,IF(MID(J35,5,1)="-",DATE(LEFT(J35,4),MID(J35,6,2),RIGHT(J35,2)),IF(MID(J35,5,1)="/",DATE(LEFT(J35,4),MID(J35,6,2),RIGHT(J35,2)),DATE(RIGHT(J35,4),MID(J35,4,2),LEFT(J35,2)))))) -> 45599 | O35: =IFERROR(C35/D35,0) -> 0.031947722 | P35: =IFERROR(E35/C35,0) -> 1.3328977 | Q35: =IFERROR(E35/F35,0) -> 12.346842 | R35: =IFERROR(E35/G35,0) -> 33.512857 | S35: =IFERROR(I35/E35,0) -> 7.2893133
A36: A1034 | B36: Data Analytics Course | C36: 121 | D36: 5610 | E36: 214.96 | F36: 23 | G36: 8 | H36: 0.046 | I36: 1505 | J36: 45621 | K36: Hyderabad | L36: Mobile | M36: data analytics course | N36: =IF(A36="","",IF(ISNUMBER(J36),J36,IF(MID(J36,5,1)="-",DATE(LEFT(J36,4),MID(J36,6,2),RIGHT(J36,2)),IF(MID(J36,5,1)="/",DATE(LEFT(J36,4),MID(J36,6,2),RIGHT(J36,2)),DATE(RIGHT(J36,4),MID(J36,4,2),LEFT(J36,2)))))) -> 45621 | O36: =IFERROR(C36/D36,0) -> 0.021568627 | P36: =IFERROR(E36/C36,0) -> 1.7765289 | Q36: =IFERROR(E36/F36,0) -> 9.346087 | R36: =IFERROR(E36/G36,0) -> 26.87 | S36: =IFERROR(I36/E36,0) -> 7.0013026
A37: A1035 | B37: Data Analytics Course | C37: 104 | D37: 5275 | E37: 236.48 | F37: 16 | G37: 9 | H37: 0.031 | I37: 1824 | J37: 45302 | K37: Hyderabad | L37: Desktop | M37: data anaytics training | N37: =IF(A37="","",IF(ISNUMBER(J37),J37,IF(MID(J37,5,1)="-",DATE(LEFT(J37,4),MID(J37,6,2),RIGHT(J37,2)),IF(MID(J37,5,1)="/",DATE(LEFT(J37,4),MID(J37,6,2),RIGHT(J37,2)),DATE(RIGHT(J37,4),MID(J37,4,2),LEFT(J37,2)))))) -> 45302 | O37: =IFERROR(C37/D37,0) -> 0.01971564 | P37: =IFERROR(E37/C37,0) -> 2.2738462 | Q37: =IFERROR(E37/F37,0) -> 14.78 | R37: =IFERROR(E37/G37,0) -> 26.275556 | S37: =IFERROR(I37/E37,0) -> 7.7131258
A38: A1036 | B38: Data Analytics Course | C38: 146 | D38: 5939 | E38: 242.9 | F38: 11 | G38: 8 | H38: 0.035 | I38: 1833 | J38: 45603 | K38: Hyderabad | L38: Desktop | M38: data anaytics training | N38: =IF(A38="","",IF(ISNUMBER(J38),J38,IF(MID(J38,5,1)="-",DATE(LEFT(J38,4),MID(J38,6,2),RIGHT(J38,2)),IF(MID(J38,5,1)="/",DATE(LEFT(J38,4),MID(J38,6,2),RIGHT(J38,2)),DATE(RIGHT(J38,4),MID(J38,4,2),LEFT(J38,2)))))) -> 45603 | O38: =IFERROR(C38/D38,0) -> 0.024583263 | P38: =IFERROR(E38/C38,0) -> 1.6636986 | Q38: =IFERROR(E38/F38,0) -> 22.081818 | R38: =IFERROR(E38/G38,0) -> 30.3625 | S38: =IFERROR(I38/E38,0) -> 7.5463154
A39: A1037 | B39: Data Analytics Course | C39: 123 | D39: 5131 | E39: 215.57 | F39: 19 | G39: 5 | H39: 0.041 | I39: 1307 | J39: 45546 | K39: Hyderabad | L39: Mobile | M39: learn data analytics | N39: =IF(A39="","",IF(ISNUMBER(J39),J39,IF(MID(J39,5,1)="-",DATE(LEFT(J39,4),MID(J39,6,2),RIGHT(J39,2)),IF(MID(J39,5,1)="/",DATE(LEFT(J39,4),MID(J39,6,2),RIGHT(J39,2)),DATE(RIGHT(J39,4),MID(J39,4,2),LEFT(J39,2)))))) -> 45546 | O39: =IFERROR(C39/D39,0) -> 0.023971935 | P39: =IFERROR(E39/C39,0) -> 1.7526016 | Q39: =IFERROR(E39/F39,0) -> 11.345789 | R39: =IFERROR(E39/G39,0) -> 43.114 | S39: =IFERROR(I39/E39,0) -> 6.0629958
A40: A1038 | B40: Data Analytics Course | C40: 90 | D40: 5786 | E40: 197.55 | F40: 11 | G40: 6 | H40: 0.043 | I40: 1704 | J40: 16-11-2024 | K40: Hyderabad | L40: Mobile | M40: online data analytic | N40: =IF(A40="","",IF(ISNUMBER(J40),J40,IF(MID(J40,5,1)="-",DATE(LEFT(J40,4),MID(J40,6,2),RIGHT(J40,2)),IF(MID(J40,5,1)="/",DATE(LEFT(J40,4),MID(J40,6,2),RIGHT(J40,2)),DATE(RIGHT(J40,4),MID(J40,4,2),LEFT(J40,2)))))) -> 45612 | O40: =IFERROR(C40/D40,0) -> 0.015554787 | P40: =IFERROR(E40/C40,0) -> 2.195 | Q40: =IFERROR(E40/F40,0) -> 17.959091 | R40: =IFERROR(E40/G40,0) -> 32.925 | S40: =IFERROR(I40/E40,0) -> 8.6256644
...

Sheet Statistics
A1: Metric | B1: Mean | C1: Median | D1: Mode | E1: Standard Deviation
A2: Clicks | B2: =AVERAGE(Cleaned_Data!C2:C2601) -> 138.95885 | C2: =MEDIAN(Cleaned_Data!C2:C2601) -> 139 | D2: =MODE(Cleaned_Data!C2:C2601) -> 139 | E2: =STDEV(Cleaned_Data!C2:C2601) -> 33.865228
A3: Impressions | B3: =AVERAGE(Cleaned_Data!E2:E2601) -> 215.10851 | C3: =MEDIAN(Cleaned_Data!D2:D2601) -> 4518.5 | D3: =MODE(Cleaned_Data!D2:D2601) -> 4518.5 | E3: =STDEV(Cleaned_Data!D2:D2601) -> 860.8434
A4: Cost | B4: =AVERAGE(Cleaned_Data!E2:E2601) -> 215.10851 | C4: =MEDIAN(Cleaned_Data!E2:E2601) -> 215.57 | D4: =MODE(Cleaned_Data!E2:E2601) -> 215.57 | E4: =+STDEV(Cleaned_Data!E2:E2601) -> 19.90758
A5: Leads | B5: =AVERAGE(Cleaned_Data!F2:F2601) -> 20.003846 | C5: =MEDIAN(Cleaned_Data!F2:F2601) -> 20 | D5: =MODE(Cleaned_Data!F2:F2601) -> 20 | E5: =STDEV(Cleaned_Data!F2:F2601) -> 5.9763533
A6: Conversions | B6: =AVERAGE(Cleaned_Data!G2:G2601) -> 6.5326923 | C6: =MEDIAN(Cleaned_Data!G2:G2601) -> 7 | D6: =MODE(Cleaned_Data!G2:G2601) -> 7 | E6: =STDEV(Cleaned_Data!G2:G2601) -> 2.2414148
A7: Sale_Amount | B7: =AVERAGE(Cleaned_Data!I2:I2601) -> 1498.9877 | C7: =MEDIAN(Cleaned_Data!I2:I2601) -> 1505 | D7: =MODE(Cleaned_Data!I2:I2601) -> 1505 | E7: =STDEV(Cleaned_Data!I2:I2601) -> 279.32721
A8: CTR | B8: =AVERAGE(Cleaned_Data!O2:O2601) -> 0.031927223 | C8: =MEDIAN(Cleaned_Data!O2:O2601) -> 0.030384186 | D8: =MODE(Cleaned_Data!O2:O2601) -> 0.027027027 | E8: =STDEV(Cleaned_Data!O2:O2601) -> 0.010277003
A9: Conversion Rate | B9: =AVERAGE(Cleaned_Data!H2:H2601) -> 0.048261923 | C9: =MEDIAN(Cleaned_Data!H2:H2601) -> 0.046 | D9: =MODE(Cleaned_Data!H2:H2601) -> 0.046 | E9: =STDEV(Cleaned_Data!H2:H2601) -> 0.017461116

Sheet Formula Analysis
A1: Device | B1: Count | D1: Metric | E1: Total | G1: Column1 | H1: Column2
A2: Desktop | B2: =COUNTIF(Cleaned_Data!L2:L2601,A2) -> 888 | D2: Clicks | E2: =SUM(Cleaned_Data!C2:C2601) -> 361293 | G2: Date | H2: Formatted Date
A3: Mobile | B3: =COUNTIF(Cleaned_Data!L3:L2602,A3) -> 878 | D3: Cost | E3: =SUM(Cleaned_Data!E2:E2601) -> 559282.12 | G3: First Ad Date | H3: =TEXT(Cleaned_Data!N2,"dd-mmm-yyyy") -> 16-Nov-2024
A4: Tablet | B4: =COUNTIF(Cleaned_Data!L4:L2603,A4) -> 834 | D4: Sale Amount | E4: =SUM(Cleaned_Data!I2:I2601) -> 3897368
A7: Insight | B7: Finding
A8: Total Clicks | B8: 361293
A9: Total Cost | B9: 559282.12
A10: Total Sale Amount | B10: 3897368
A11: Highest Sales Device | B11: Desktop
A12: Highest Conversion Device | B12: Desktop
A13: Highest Clicks Device | B13: Mobile
A14: Lowest Sales Device | B14: Tablet
